<?xml version="1.0" ?>
<!-- =================================================================================== -->
<!-- |    This document was autogenerated by xacro from robot.xacro                    | -->
<!-- |    EDITING THIS FILE BY HAND IS NOT RECOMMENDED                                 | -->
<!-- =================================================================================== -->
<robot name="UsefulHound" xmlns:xacro="http://www.ros.org/wiki/xacro">
  <material name="black">
    <color rgba="0.0 0.0 0.0 1.0"/>
  </material>
  <material name="blue">
    <color rgba="0.2 0.2 0.8 1.0"/>
  </material>
  <material name="green">
    <color rgba="0.0 0.8 0.0 1.0"/>
  </material>
  <material name="grey">
    <color rgba="0.2 0.2 0.2 1.0"/>
  </material>
  <material name="silver">
    <color rgba="0.913725490196 0.913725490196 0.847058823529 1.0"/>
  </material>
  <material name="orange">
    <color rgba="1.0 0.423529411765 0.0392156862745 1.0"/>
  </material>
  <material name="brown">
    <color rgba="0.870588235294 0.811764705882 0.764705882353 1.0"/>
  </material>
  <material name="red">
    <color rgba="0.8 0.0 0.0 1.0"/>
  </material>
  <material name="white">
    <color rgba="1.0 1.0 1.0 1.0"/>
  </material>

  <link name="trunk">
    <visual>
      <origin rpy="0 0 0" xyz="0 0 0"/>
      <geometry>
        <mesh filename="base__.dae" scale="1 1 1"/>
      </geometry>
      <material name="blue"/>
    </visual>
    <collision>
      <origin rpy="0 0 0" xyz="0 0 0"/>
      <geometry>
	<!--<box size="0.562 0.335 0.14"/>-->
        <box size="0.562 0.185 0.08"/>
      </geometry>
    </collision>
    <inertial>
      <origin rpy="0 0 0" xyz="-0.001319 -0.000239 -0.003879"/>
      <mass value="18.476235"/>
      <inertia ixx="0.217213" ixy="0.001430" ixz="0.002076" iyy="0.803514" iyz="0.000309" izz="0.958084"/>
    </inertial>
  </link>

  <joint name="RR_roll_joint" type="revolute">
    <origin rpy="0 0 0" xyz="-0.349 -0.100 0.000"/>
    <parent link="trunk"/>
    <child link="RR_shoulder"/>
    <axis xyz="1 0 0"/>
    <!--dynamics rotor_inertia="0.01432664" damping="0" friction="0"/-->
    <limit effort="200" lower="-1.48352986419518" upper="1.48352986419518" velocity="21.29"/>
  </joint>
  <link name="RR_shoulder">
    <visual>
      <origin rpy="0 0 0" xyz="0 0 0"/>
      <geometry>
        <mesh filename="shoulder_mirror__.dae" scale="1 1 1"/>
      </geometry>
      <material name="grey"/>
    </visual>
    <collision>
      <origin rpy="1.57079632679 0 0" xyz="0 -0.0125 0"/>
      <geometry>
        <cylinder length="0.133" radius="0.0605"/>
      </geometry>
    </collision>
    <inertial>
      <origin rpy="0 0 0" xyz="-0.00572291 -0.00984486 0.00000918"/>
      <mass value="4.1828477"/>
      <inertia ixx="0.01020686" ixy="-0.00005695" ixz="-0.00001248" iyy="0.00830726" iyz="-0.00009489" izz="0.01176863"/>
    </inertial>
  </link>
  <joint name="RR_hip_joint" type="revolute">
    <origin rpy="0 0 0" xyz="0 -0.1135 0"/>
    <parent link="RR_shoulder"/>
    <child link="RR_thigh"/>
    <axis xyz="0 1 0"/>
    <!--dynamics rotor_inertia="0.05581304" damping="0" friction="0"/-->
    <limit effort="200" lower="-6.28318530718" upper="6.28318530718" velocity="21.29"/>
  </joint>
  <link name="RR_thigh">
    <visual>
      <origin rpy="0 0 0" xyz="0 0 0"/>
      <geometry>
        <mesh filename="thigh_mirror__.dae" scale="1 1 1"/>
      </geometry>
      <material name="grey"/>
    </visual>
    <collision>
      <origin rpy="0 0 0" xyz="0 0 -0.16395"/>
      <geometry>
        <box size="0.078 0.069 0.35"/>
      </geometry>
    </collision>
    <inertial>
      <origin rpy="0 0 0" xyz="0.01353461 0.01879181 -0.09638993"/>
      <mass value="1.52408165"/>
      <inertia ixx="0.02365733" ixy="-0.00036775" ixz="-0.00293293" iyy="0.02323490" iyz="0.00261899" izz="0.00318143"/>
    </inertial>
  </link>
  <joint name="RR_knee_joint" type="revolute">
    <origin rpy="0 0 0" xyz="0 0 -0.3279"/>
    <parent link="RR_thigh"/>
    <child link="RR_calf"/>
    <axis xyz="0 1 0"/>
    <!--dynamics rotor_inertia="0.0561" damping="0" friction="0"/-->
    <limit effort="400" lower="-2.7925268" upper="2.7925268" velocity="10.0"/>
  </joint>
  <link name="RR_calf">
    <visual>
      <origin rpy="0 0 0" xyz="0 0 0"/>
      <geometry>
        <mesh filename="calf__.dae" scale="1 1 1"/>
      </geometry>
      <material name="silver"/>
    </visual>
    <collision>
      <origin rpy="0 0 0" xyz="0 0 -0.175"/>
      <geometry>
        <box size="0.032 0.032 0.347"/>
      </geometry>
    </collision>
    <inertial>
      <origin rpy="0 0 0" xyz="0.00000000 -0.00007139 -0.1020159"/>
      <mass value="0.6070551"/>
      <inertia ixx="0.0103107" ixy="0.00000000" ixz="0.0001390" iyy="0.0103192" iyz="-0.0000046" izz="0.0004140"/>
    </inertial>
  </link>
  <joint name="RR_foot_fixed" type="fixed">
    <origin rpy="0 0 0" xyz="0 0 -0.347"/>
    <parent link="RR_calf"/>
    <child link="RR_foot"/>
  </joint>
  <link name="RR_foot">
    <visual>
      <origin rpy="0 0 0" xyz="0 0 0"/>
      <geometry>
        <sphere radius="0.039"/>
      </geometry>
    </visual>
    <collision>
      <origin rpy="0 0 0" xyz="0 0 0"/>
      <geometry>
        <sphere radius="0.039"/>
      </geometry>
    </collision>
    <inertial>
      <origin rpy="0 0 0" xyz="0.0 -0.0 -0.0"/>
      <mass value="0.01"/>
      <inertia ixx="0.0000001" ixy="0.0" ixz="-0.0" iyy="0.0000001" iyz="-0.0" izz="0.0.0000001"/>
    </inertial>
  </link>


  <joint name="RL_roll_joint" type="revolute">
    <origin rpy="0 0 0" xyz="-0.349 0.100 0.000"/>
    <parent link="trunk"/>
    <child link="RL_shoulder"/>
    <axis xyz="1 0 0"/>
    <!--dynamics rotor_inertia="0.01432664" damping="0" friction="0"/-->
    <limit effort="200" lower="-1.48352986419518" upper="1.48352986419518" velocity="21.29"/>
  </joint>
  <link name="RL_shoulder">
    <visual>
      <origin rpy="0 0 0" xyz="0 0 0"/>
      <geometry>
        <mesh filename="shoulder__.dae" scale="1 1 1"/>
      </geometry>
      <material name="grey"/>
    </visual>
    <collision>
      <origin rpy="1.57079632679 0 0" xyz="0 0.0125 0"/>
      <geometry>
        <cylinder length="0.133" radius="0.0605"/>
      </geometry>
    </collision>
    <inertial>
      <origin rpy="0 0 0" xyz="-0.00572291 0.00984486 0.00000918"/>
      <mass value="4.1828477"/>
      <inertia ixx="0.01020686" ixy="0.00005695" ixz="-0.00001248" iyy="0.00830726" iyz="0.00009489" izz="0.01176863"/>
    </inertial>
  </link>
  <joint name="RL_hip_joint" type="revolute">
    <origin rpy="0 0 0" xyz="0 0.1135 0"/>
    <parent link="RL_shoulder"/>
    <child link="RL_thigh"/>
    <axis xyz="0 1 0"/>
    <!--dynamics rotor_inertia="0.05581304" damping="0" friction="0"/-->
    <limit effort="200" lower="-6.28318530718" upper="6.28318530718" velocity="21.29"/>
  </joint>
  <link name="RL_thigh">
    <visual>
      <origin rpy="0 0 0" xyz="0 0 0"/>
      <geometry>
        <mesh filename="thigh__.dae" scale="1 1 1"/>
      </geometry>
      <material name="grey"/>
    </visual>
    <collision>
      <origin rpy="0 0 0" xyz="0 0 -0.16395"/>
      <geometry>
        <box size="0.078 0.069 0.35"/>
      </geometry>
    </collision>
    <inertial>
      <origin rpy="0 0 0" xyz="0.01353461 -0.01879181 -0.09638993"/>
      <mass value="1.52408165"/>
      <inertia ixx="0.02365733" ixy="0.00036775" ixz="-0.00293293" iyy="0.02323490" iyz="-0.00261899" izz="0.00318143"/>
    </inertial>
  </link>
  <joint name="RL_knee_joint" type="revolute">
    <origin rpy="0 0 0" xyz="0 0 -0.3279"/>
    <parent link="RL_thigh"/>
    <child link="RL_calf"/>
    <axis xyz="0 1 0"/>
    <!--dynamics rotor_inertia="0.0561" damping="0" friction="0"/-->
    <limit effort="400" lower="-2.7925268" upper="2.7925268" velocity="10.0"/>
  </joint>
  <link name="RL_calf">
    <visual>
      <origin rpy="0 0 0" xyz="0 0 0"/>
      <geometry>
        <mesh filename="calf__.dae" scale="1 1 1"/>
      </geometry>
      <material name="silver"/>
    </visual>
    <collision>
      <origin rpy="0 0 0" xyz="0 0 -0.175"/>
      <geometry>
        <box size="0.032 0.032 0.347"/>
      </geometry>
    </collision>
    <inertial>
      <origin rpy="0 0 0" xyz="0.00000000 0.00007139 -0.1020159"/>
      <mass value="0.6070551"/>
      <inertia ixx="0.0103107" ixy="0.00000000" ixz="0.0001390" iyy="0.0103192" iyz="-0.0000046" izz="0.0004140"/>
    </inertial>
  </link>
  <joint name="RL_foot_fixed" type="fixed">
    <origin rpy="0 0 0" xyz="0 0 -0.347"/>
    <parent link="RL_calf"/>
    <child link="RL_foot"/>
  </joint>
  <link name="RL_foot">
    <visual>
      <origin rpy="0 0 0" xyz="0 0 0"/>
      <geometry>
        <sphere radius="0.039"/>
      </geometry>
    </visual>
    <collision>
      <origin rpy="0 0 0" xyz="0 0 0"/>
      <geometry>
        <sphere radius="0.039"/>
      </geometry>
    </collision>
    <inertial>
      <origin rpy="0 0 0" xyz="0.0 -0.0 -0.0"/>
      <mass value="0.01"/>
      <inertia ixx="0.0000001" ixy="0.0" ixz="-0.0" iyy="0.0000001" iyz="-0.0" izz="0.0.0000001"/>
    </inertial>
  </link>


  <joint name="FR_roll_joint" type="revolute">
    <origin rpy="0 0 0" xyz="0.349 -0.100 0.000"/>
    <parent link="trunk"/>
    <child link="FR_shoulder"/>
    <axis xyz="1 0 0"/>
    <!--dynamics rotor_inertia="0.01432664" damping="0" friction="0"/-->
    <limit effort="200" lower="-1.48352986419518" upper="1.48352986419518" velocity="21.29"/>
  </joint>
  <link name="FR_shoulder">
    <visual>
      <origin rpy="0 0 0" xyz="0 0 0"/>
      <geometry>
        <mesh filename="shoulder_mirror__.dae" scale="1 1 1"/>
      </geometry>
      <material name="grey"/>
    </visual>
    <collision>
      <origin rpy="1.57079632679 0 0" xyz="0 -0.0125 0"/>
      <geometry>
        <cylinder length="0.133" radius="0.0605"/>
      </geometry>
    </collision>
    <inertial>
      <origin rpy="0 0 0" xyz="-0.00572291 -0.00984486 0.00000918"/>
      <mass value="4.1828477"/>
      <inertia ixx="0.01020686" ixy="-0.00005695" ixz="-0.00001248" iyy="0.00830726" iyz="-0.00009489" izz="0.01176863"/>
    </inertial>
  </link>
  <joint name="FR_hip_joint" type="revolute">
    <origin rpy="0 0 0" xyz="0 -0.1135 0"/>
    <parent link="FR_shoulder"/>
    <child link="FR_thigh"/>
    <axis xyz="0 1 0"/>
    <!--dynamics rotor_inertia="0.05581304" damping="0" friction="0"/-->
    <limit effort="200" lower="-6.28318530718" upper="6.28318530718" velocity="21.29"/>
  </joint>
  <link name="FR_thigh">
    <visual>
      <origin rpy="0 0 0" xyz="0 0 0"/>
      <geometry>
        <mesh filename="thigh_mirror__.dae" scale="1 1 1"/>
      </geometry>
      <material name="grey"/>
    </visual>
    <collision>
      <origin rpy="0 0 0" xyz="0 0 -0.16395"/>
      <geometry>
        <box size="0.078 0.069 0.35"/>
      </geometry>
    </collision>
    <inertial>
      <origin rpy="0 0 0" xyz="0.01353461 0.01879181 -0.09638993"/>
      <mass value="1.52408165"/>
      <inertia ixx="0.02365733" ixy="-0.00036775" ixz="-0.00293293" iyy="0.02323490" iyz="0.00261899" izz="0.00318143"/>
    </inertial>
  </link>
  <joint name="FR_knee_joint" type="revolute">
    <origin rpy="0 0 0" xyz="0 0 -0.3279"/>
    <parent link="FR_thigh"/>
    <child link="FR_calf"/>
    <axis xyz="0 1 0"/>
    <!--dynamics rotor_inertia="0.0561" damping="0" friction="0"/-->
    <limit effort="400" lower="-2.7925268" upper="2.7925268" velocity="10.0"/>
  </joint>
  <link name="FR_calf">
    <visual>
      <origin rpy="0 0 0" xyz="0 0 0"/>
      <geometry>
        <mesh filename="calf__.dae" scale="1 1 1"/>
      </geometry>
      <material name="silver"/>
    </visual>
    <collision>
      <origin rpy="0 0 0" xyz="0 0 -0.175"/>
      <geometry>
        <box size="0.032 0.032 0.347"/>
      </geometry>
    </collision>
    <inertial>
      <origin rpy="0 0 0" xyz="0.00000000 -0.00007139 -0.1020159"/>
      <mass value="0.6070551"/>
      <inertia ixx="0.0103107" ixy="0.00000000" ixz="0.0001390" iyy="0.0103192" iyz="-0.0000046" izz="0.0004140"/>
    </inertial>
  </link>
  <joint name="FR_foot_fixed" type="fixed">
    <origin rpy="0 0 0" xyz="0 0 -0.347"/>
    <parent link="FR_calf"/>
    <child link="FR_foot"/>
  </joint>
  <link name="FR_foot">
    <visual>
      <origin rpy="0 0 0" xyz="0 0 0"/>
      <geometry>
        <sphere radius="0.039"/>
      </geometry>
    </visual>
    <collision>
      <origin rpy="0 0 0" xyz="0 0 0"/>
      <geometry>
        <sphere radius="0.039"/>
      </geometry>
    </collision>
    <inertial>
      <origin rpy="0 0 0" xyz="0.0 -0.0 -0.0"/>
      <mass value="0.01"/>
      <inertia ixx="0.0000001" ixy="0.0" ixz="-0.0" iyy="0.0000001" iyz="-0.0" izz="0.0.0000001"/>
    </inertial>
  </link>


  <joint name="FL_roll_joint" type="revolute">
    <origin rpy="0 0 0" xyz="0.349 0.100 0.000"/>
    <parent link="trunk"/>
    <child link="FL_shoulder"/>
    <axis xyz="1 0 0"/>
    <!--dynamics rotor_inertia="0.01432664" damping="0" friction="0"/-->
    <limit effort="200" lower="-1.48352986419518" upper="1.48352986419518" velocity="21.29"/>
  </joint>
  <link name="FL_shoulder">
    <visual>
      <origin rpy="0 0 0" xyz="0 0 0"/>
      <geometry>
        <mesh filename="shoulder__.dae" scale="1 1 1"/>
      </geometry>
      <material name="grey"/>
    </visual>
    <collision>
      <origin rpy="1.57079632679 0 0" xyz="0 0.0125 0"/>
      <geometry>
        <cylinder length="0.133" radius="0.0605"/>
      </geometry>
    </collision>
    <inertial>
      <origin rpy="0 0 0" xyz="-0.00572291 0.00984486 0.00000918"/>
      <mass value="4.1828477"/>
      <inertia ixx="0.01020686" ixy="0.00005695" ixz="-0.00001248" iyy="0.00830726" iyz="0.00009489" izz="0.01176863"/>
    </inertial>
  </link>
  <joint name="FL_hip_joint" type="revolute">
    <origin rpy="0 0 0" xyz="0 0.1135 0"/>
    <parent link="FL_shoulder"/>
    <child link="FL_thigh"/>
    <axis xyz="0 1 0"/>
    <!--dynamics rotor_inertia="0.05581304" damping="0" friction="0"/-->
    <limit effort="200" lower="-6.28318530718" upper="6.28318530718" velocity="21.29"/>
  </joint>
  <link name="FL_thigh">
    <visual>
      <origin rpy="0 0 0" xyz="0 0 0"/>
      <geometry>
        <mesh filename="thigh__.dae" scale="1 1 1"/>
      </geometry>
      <material name="grey"/>
    </visual>
    <collision>
      <origin rpy="0 0 0" xyz="0 0 -0.16395"/>
      <geometry>
        <box size="0.078 0.069 0.35"/>
      </geometry>
    </collision>
    <inertial>
      <origin rpy="0 0 0" xyz="0.01353461 -0.01879181 -0.09638993"/>
      <mass value="1.52408165"/>
      <inertia ixx="0.02365733" ixy="0.00036775" ixz="-0.00293293" iyy="0.02323490" iyz="-0.00261899" izz="0.00318143"/>
    </inertial>
  </link>
  <joint name="FL_knee_joint" type="revolute">
    <origin rpy="0 0 0" xyz="0 0 -0.3279"/>
    <parent link="FL_thigh"/>
    <child link="FL_calf"/>
    <axis xyz="0 1 0"/>
    <!--dynamics rotor_inertia="0.0561" damping="0" friction="0"/-->
    <limit effort="400" lower="-2.7925268" upper="2.7925268" velocity="10.0"/>
  </joint>
  <link name="FL_calf">
    <visual>
      <origin rpy="0 0 0" xyz="0 0 0"/>
      <geometry>
        <mesh filename="calf__.dae" scale="1 1 1"/>
      </geometry>
      <material name="silver"/>
    </visual>
    <collision>
      <origin rpy="0 0 0" xyz="0 0 -0.175"/>
      <geometry>
        <box size="0.032 0.032 0.347"/>
      </geometry>
    </collision>
    <inertial>
      <origin rpy="0 0 0" xyz="0.00000000 0.00007139 -0.1020159"/>
      <mass value="0.6070551"/>
      <inertia ixx="0.0103107" ixy="0.00000000" ixz="0.0001390" iyy="0.0103192" iyz="-0.0000046" izz="0.0004140"/>
    </inertial>
  </link>
  <joint name="FL_foot_fixed" type="fixed">
    <origin rpy="0 0 0" xyz="0 0 -0.347"/>
    <parent link="FL_calf"/>
    <child link="FL_foot"/>
  </joint>
  <link name="FL_foot">
    <visual>
      <origin rpy="0 0 0" xyz="0 0 0"/>
      <geometry>
        <sphere radius="0.039"/>
      </geometry>
    </visual>
    <collision>
      <origin rpy="0 0 0" xyz="0 0 0"/>
      <geometry>
        <sphere radius="0.039"/>
      </geometry>
    </collision>
    <inertial>
      <origin rpy="0 0 0" xyz="0.0 -0.0 -0.0"/>
      <mass value="0.01"/>
      <inertia ixx="0.0000001" ixy="0.0" ixz="-0.0" iyy="0.0000001" iyz="-0.0" izz="0.0.0000001"/>
    </inertial>
  </link>

<!-- arm link -->
  <joint name="fixed" type="fixed">
    <origin xyz="0.15 0 0.05" rpy="0 0 0"/>
    <parent link="trunk"/>
    <child link="link1"/>
  </joint>

  <link name="link1">
    <visual>
      <origin xyz="0 0 0" rpy="0 0 0"/>
      <!-- <origin xyz="0.15 0 0.05" rpy="0 0 0"/> -->
      <geometry>
        <mesh filename="link1.stl" scale="0.001 0.001 0.001"/>
      </geometry>
      <material name="grey"/>
    </visual>

    <collision>
      <origin xyz="0 0 0" rpy="0 0 0"/>
      <!-- <origin xyz="0.15 0 0.05" rpy="0 0 0"/> -->
      <geometry>
        <mesh filename="link1.stl" scale="0.001 0.001 0.001"/>
      </geometry>
    </collision>

    <inertial>
      <origin xyz="0.0000000e+00 -1.7653633e-04 -1.0030209e-03" rpy="0 0 0"/>
      <mass value="9.4360595e-01"/>
      <inertia ixx="1.0e-03" ixy="0.0" ixz="0.0" 
               iyx="0.0" iyy="1.0e-03" iyz="0.0" 
               izx="0.0" izy="0.0" izz="1.0e-03" />
    </inertial>
  </link>
  
  <!-- Joint 1 -->
  <joint name="joint1" type="revolute">
    <parent link="link1"/>
    <child link="link2"/>
    <origin xyz="0.0 0.0 0.126" rpy="0 0 0"/>
    <axis xyz="0 0 1"/>
    <limit velocity="6.5" effort="1000" lower="-1.57" upper="1.57" />
    <dynamics damping="0.7"/>
  </joint>

  <!-- link 2 -->
  <link name="link2">
    <visual>
      <origin xyz="0 0 0" rpy="0 0 0"/>
      <geometry>
        <mesh filename="link2.stl" scale="0.001 0.001 0.001"/>
      </geometry>
      <material name="grey"/>
    </visual>

    <collision>
      <origin xyz="0 0 0" rpy="0 0 0"/>
      <geometry>
        <mesh filename="link2.stl" scale="0.001 0.001 0.001"/>
      </geometry>
    </collision>
    
    <inertial>
      <origin xyz="0.0000000e+00 -1.7653633e-04 -1.0030209e-03" rpy="0 0 0"/>
      <mass value="9.4360595e-01"/>
      <inertia ixx="1.5694005e-03" ixy="0.0" ixz="0.0" 
               iyx="0.0" iyy="4.5593385e-04" iyz="6.4581824e-09" 
               izx="0.0" izy="6.4581824e-09" izz="1.5561809e-03" />
    </inertial>
  </link>

  <!-- Joint 2 -->
  <joint name="joint2" type="revolute">
    <parent link="link2"/>
    <child link="link3"/>
    <origin xyz="0.0 0.069 0.033" rpy="0 0 0"/>
    <axis xyz="0 1 0"/>
    <limit velocity="6.5" effort="1000" lower="-1.57" upper="1.57" />
    <dynamics damping="0.7"/>
  </joint>

  <!-- link 3 -->
  <link name="link3">
    <visual>
      <origin xyz="0 0 0" rpy="0 0 0"/>
      <geometry>
        <mesh filename="link3.stl" scale="0.001 0.001 0.001"/>
      </geometry>
      <material name="grey"/>
    </visual>

    <collision>
      <origin xyz="0 0 0" rpy="0 0 0"/>
      <geometry>
        <mesh filename="link3.stl" scale="0.001 0.001 0.001"/>
      </geometry>
    </collision>

    <inertial>
      <origin xyz="1.5751501e-02 -2.2073221e-04 1.9913687e-01" rpy="0 0 0"/>
      <mass value="1.3825862e+00"/>
      <inertia ixx="6.7630430e-02" ixy="-1.9988597e-05" ixz="-5.7477571e-03" 
               iyx="-1.9988597e-05" iyy="6.7208001e-02" iyz="7.4823203e-05" 
               izx="-5.7477571e-03" izy="7.4823203e-05" izz="2.6031353e-03" />
    </inertial>
  </link>

  <!-- Joint 3 -->
  <joint name="joint3" type="revolute">
    <parent link="link3"/>
    <child link="link4"/>
    <origin xyz="0.03000 -0.01150 0.26400" rpy="0 0 0"/>
    <axis xyz="0 1 0"/>
    <limit velocity="6.5" effort="1000" lower="-1.57" upper="1.57" />
    <dynamics damping="0.7"/>
  </joint>

  <!-- link 4 -->
  <link name="link4">
    <visual>
      <origin xyz="0 0 0" rpy="0 0 0"/>
      <geometry>
        <mesh filename="link4.stl" scale="0.001 0.001 0.001"/>
      </geometry>
      <material name="grey"/>
    </visual>

    <collision>
      <origin xyz="0 0 0" rpy="0 0 0"/>
      <geometry>
        <mesh filename="link4.stl" scale="0.001 0.001 0.001"/>
      </geometry>
    </collision>

    <inertial>
      <origin xyz="3.0352597e-04 4.1703880e-05 3.8074728e-01" rpy="0 0 0"/>
      <mass value="1.2126965e+00"/>
      <inertia ixx="1.7985424e-01" ixy="-9.9417476e-07" ixz="-8.1564441e-05" 
               iyx="-9.9417476e-07" iyy="1.7948679e-01" iyz="-1.7705853e-05" 
               izx="-8.1564441e-05" izy="-1.7705853e-05" izz="1.1422079e-03" />
    </inertial>
  </link>

  <!-- Joint 4 -->
  <joint name="joint4" type="revolute">
    <parent link="link4"/>
    <child link="link5"/>
    <origin xyz="0.19500 -0.05750 0.03000" rpy="0 0 0"/>
    <axis xyz="1 0 0"/>
    <limit velocity="6.5" effort="1000" lower="-1.57" upper="1.57" />
    <dynamics damping="0.7"/>
  </joint>

  <!-- link 5 -->
  <link name="link5">
    <visual>
      <origin xyz="0 0 0" rpy="0 0 0"/>
      <geometry>
        <mesh filename="link5.stl" scale="0.001 0.001 0.001"/>
      </geometry>
      <material name="grey"/>
    </visual>

    <collision>
      <origin xyz="0 0 0" rpy="0 0 0"/>
      <geometry>
        <mesh filename="link5.stl" scale="0.001 0.001 0.001"/>
      </geometry>
    </collision>

    <inertial>
      <origin xyz="-2.1388493e-06 -2.2290515e-03 5.1387207e-01" rpy="0 0 0"/>
      <mass value="4.6635550e-01"/>
      <inertia ixx="1.2357713e-01" ixy="-1.9465317e-09" ixz="5.1228604e-07" 
               iyx="-1.9465317e-09" iyy="1.2339567e-01" iyz="5.3769657e-04" 
               izx="5.1228604e-07" izy="5.3769657e-04" izz="3.3216863e-04" />
    </inertial>
  </link>

  <!-- Joint 5 -->
  <joint name="joint5" type="revolute">
    <parent link="link5"/>
    <child link="link6"/>
    <origin xyz="0.06300 0.04500 0.00000" rpy="0 0 0"/>
    <axis xyz="0 1 0"/>
    <limit velocity="6.5" effort="1000" lower="-1.57" upper="1.57" />
    <dynamics damping="0.7"/>
  </joint>

  <!-- link 6 -->
  <link name="link6">
    <visual>
      <origin xyz="0 0 0" rpy="0 0 0"/>
      <geometry>
        <mesh filename="link6.stl" scale="0.001 0.001 0.001"/>
      </geometry>
      <material name="grey"/>
    </visual>

    <collision>
      <origin xyz="0 0 0" rpy="0 0 0"/>
      <geometry>
        <mesh filename="link6.stl" scale="0.001 0.001 0.001"/>
      </geometry>
    </collision>

    <inertial>
      <origin xyz="-2.1268822e-06 1.8039922e-04 5.9028250e-01" rpy="0 0 0"/>
      <mass value="4.2561606e-01"/>
      <inertia ixx="1.4881319e-01" ixy="0.0000000e+00" ixz="5.3435266e-07" 
               iyx="0.0000000e+00" iyy="1.4872708e-01" iyz="-4.3708754e-05" 
               izx="5.3435266e-07" izy="-4.3708754e-05" izz="2.1040082e-04" />
    </inertial>
  </link>

  <!-- Joint 6 -->
  <joint name="joint6" type="revolute">
    <parent link="link6"/>
    <child link="end_link"/>
    <origin xyz="0.12300 -0.04500 0.00000" rpy="0 0 0"/>
    <axis xyz="1 0 0"/>
    <limit velocity="6.5" effort="1000" lower="-1.57" upper="1.57" />
    <dynamics damping="0.7"/>
  </joint>

  <!-- end link -->
  <link name="end_link">
    <visual>
      <origin xyz="0.0 0.0 0.0" rpy="0 0 0" />
      <geometry>
        <mesh filename="end_link.stl" scale="0.001 0.001 0.001"/>
      </geometry>
      <material name="grey"/>
    </visual>

    <collision>
      <origin xyz="0.0 0.0 0.0" rpy="0 0 0" />
      <geometry>
        <mesh filename="end_link.stl" scale="0.001 0.001 0.001"/>
      </geometry>
    </collision>

    <inertial>
      <origin xyz="0.00337 0.00000 0.00000" rpy="0 0 0"/>
      <mass value="0.01919"/>
      <inertia ixx="1.25e-4" ixy="0.0" ixz="0.0" iyy="1.25e-4" iyz="0.0" izz="1.25e-4" />
    </inertial>
  </link>
</robot>